Workbook

Sheet 참조
B2: 1 | C2: 日 | D2: 休 | E2: 5000 | F2: 지출 | G2: 현금
B3: 2 | C3: 月 | D3: 勤 | E3: 1000 | F3: 수입 | G3: 카드
B4: 3 | C4: 火 | G4: 페이페이
B5: 4 | C5: 水 | G5: 라쿠텐페이
B6: 5 | C6: 木 | G6: 계좌이체
B7: 6 | C7: 金
B8: 7 | C8: 土

Sheet 2026년휴일
A1: ='2026년달력'!A1 -> 2026 | C1: 월 | D1: 일
B2: =DATE($A$1,C2,D2) -> 46023 | C2: 1 | D2: 1
B3: =DATE($A$1,C3,D3) -> 46024 | C3: 1 | D3: 2
B4: =DATE($A$1,C4,D4) -> 46025 | C4: 1 | D4: 3
B5: =DATE($A$1,C5,D5) -> 46034 | C5: 1 | D5: 12
B6: =DATE($A$1,C6,D6) -> 46064 | C6: 2 | D6: 11
B7: =DATE($A$1,C7,D7) -> 46076 | C7: 2 | D7: 23
B8: =DATE($A$1,C8,D8) -> 46101 | C8: 3 | D8: 20
B9: =DATE($A$1,C9,D9) -> 46141 | C9: 4 | D9: 29
B10: =DATE($A$1,C10,D10) -> 46145 | C10: 5 | D10: 3
B11: =DATE($A$1,C11,D11) -> 46146 | C11: 5 | D11: 4
B12: =DATE($A$1,C12,D12) -> 46147 | C12: 5 | D12: 5
B13: =DATE($A$1,C13,D13) -> 46148 | C13: 5 | D13: 6
... B25: =DATE($A$1,C25,D25) -> 46387 | C25: 12 | D25: 31

Sheet 2026저축계획
A1: 월급 | B1: 0
A2: 상여 | B2: 0
A3: 잔액 | B3: 0
C4: 지출 | D4: 0 | I4: # | J4: 년월 | K4: 저축액 | L4: 누적 | M4: 상여가산
C5: 고정비 | D5: 0 | I5: 1 | J5: 202605 | K5: =$F$9*I5 -> 0 | L5: =$B$3+K5-$Q$2 -> 0
C6: 월세 | D6: 0 | I6: 2 | J6: 202606 | K6: =$F$9*I6 -> 0 | L6: =$B$3+K6-$Q$2 -> 0
I7: 3 | J7: 202607 | K7: =$F$9*I7 -> 0 | L7: =$B$3+K7-$Q$2 -> 0
C8: 지출합계 | D8: =SUM(D4:D6) -> 0 | I8: 4 | J8: 202608 | K8: =$F$9*I8 -> 0 | L8: =$B$3+K8-$Q$2 -> 0
E9: 수입 | F9: =B1-D8 -> 0 | I9: 5 | J9: 202609 | K9: =$F$9*I9 -> 0 | L9: =$B$3+K9-$Q$2 -> 0
I10: 6 | J10: 202610 | K10: =$F$9*I10 -> 0 | L10: =$B$3+K10-$Q$2 -> 0
I11: 7 | J11: 202611 | K11: =$F$9*I11 -> 0 | L11: =$B$3+K11-$Q$2 -> 0
I12: 8 | J12: 202612 | K12: =$F$9*I12 -> 0 | L12: =$B$3+K12-$Q$2 -> 0
I13: 9 | J13: 202701 | K13: =$F$9*I13 -> 0 | L13: =$B$3+K13-$Q$2 -> 0
I14: 10 | J14: 202702 | K14: =$F$9*I14 -> 0 | L14: =$B$3+K14-$Q$2 -> 0 | M14: =$B$2+L14 -> 0

Sheet 장기계획
A1: 잔액 | B1: ='2026저축계획'!B3 -> 0
A2: 월급 | B2: ='2026저축계획'!B1 -> 0
A3: 지출 | B3: ='2026저축계획'!D8 -> 0
A4: 수입 | B4: =B2-B3 -> 0
A5: 상여 | B5: ='2026저축계획'!B2 -> 0 | I5: 계획1 | N5: 계획2 | S5: 계획3
C6: 년수 | D6: 나이 | E6: 연도(3월기준) | F6: 저축액 | G6: 잔액 | I6: 연봉 | J6: 예상월급 | K6: 저축액 | L6: 잔액 | N6: 연봉 | O6: 예상월급 | P6: 저축액 | Q6: 잔액 | S6: 연봉 | T6: 예상월급 | U6: 저축액 | V6: 잔액
C7: 1 | D7: 37 | E7: 2027 | F7: =(($B$4*10))+($B$5) -> 0 | G7: =$B$1+F7 -> 0 | I7: 500 | J7: 319200 | K7: =((J7-$B$3)*10)+($B$5) -> 3192000 | L7: =$B$1+K7 -> 3192000 | N7: 500 | O7: 319200 | P7: =((O7-$B$3)*10)+($B$5) -> 3192000 | Q7: =$B$1+P7 -> 3192000 | S7: 500 | T7: 319200 | U7: =((T7-$B$3)*10)+($B$5) -> 3192000 | V7: =$B$1+U7 -> 3192000
C8: 2 | D8: 38 | E8: 2028 | F8: =(($B$4*12))+($B$5) -> 0 | G8: =G7+F8 -> 0 | I8: 550 | J8: 352000 | K8: =((J8-$B$3)*12)+($B$5) -> 4224000 | L8: =L7+K8 -> 7416000 | N8: 550 | O8: 352000 | P8: =((O8-$B$3)*12)+($B$5) -> 4224000 | Q8: =Q7+P8 -> 7416000 | S8: 550 | T8: 352000 | U8: =((T8-$B$3)*12)+($B$5) -> 4224000 | V8: =V7+U8 -> 7416000
C9: 3 | D9: 39 | E9: 2029 | F9: =(($B$4*12))+($B$5) -> 0 | G9: =G8+F9 -> 0 | I9: 550 | J9: 352000 | K9: =((J9-$B$3)*12)+($B$5) -> 4224000 | L9: =L8+K9 -> 11640000 | N9: 550 | O9: 352000 | P9: =((O9-$B$3)*12)+($B$5) -> 4224000 | Q9: =Q8+P9 -> 11640000 | S9: 600 | T9: 382000 | U9: =((T9-$B$3)*12)+($B$5) -> 4584000 | V9: =V8+U9 -> 12000000
C10: 4 | D10: 40 | E10: 2030 | F10: =(($B$4*12))+($B$5) -> 0 | G10: =G9+F10 -> 0 | I10: 550 | J10: 352000 | K10: =((J10-$B$3)*12)+($B$5) -> 4224000 | L10: =L9+K10 -> 15864000 | N10: 600 | O10: 382000 | P10: =((O10-$B$3)*12)+($B$5) -> 4584000 | Q10: =Q9+P10 -> 16224000 | S10: 650 | T10: 415000 | U10: =((T10-$B$3)*12)+($B$5) -> 4980000 | V10: =V9+U10 -> 16980000
C11: 5 | D11: 41 | E11: 2031 | F11: =(($B$4*12))+($B$5) -> 0 | G11: =G10+F11 -> 0 | I11: 600 | J11: 382000 | K11: =((J11-$B$3)*12)+($B$5) -> 4584000 | L11: =L10+K11 -> 20448000 | N11: 600 | O11: 382000 | P11: =((O11-$B$3)*12)+($B$5) -> 4584000 | Q11: =Q10+P11 -> 20808000 | S11: 700 | T11: 441000 | U11: =((T11-$B$3)*12)+($B$5) -> 5292000 | V11: =V10+U11 -> 22272000
C12: 6 | D12: 42 | E12: 2032 | F12: =(($B$4*12))+($B$5) -> 0 | G12: =G11+F12 -> 0 | I12: 600 | J12: 382000 | K12: =((J12-$B$3)*12)+($B$5) -> 4584000 | L12: =L11+K12 -> 25032000 | N12: 650 | O12: 415000 | P12: =((O12-$B$3)*12)+($B$5) -> 4980000 | Q12: =Q11+P12 -> 25788000 | S12: 750 | T12: 468000 | U12: =((T12-$B$3)*12)+($B$5) -> 5616000 | V12: =V11+U12 -> 27888000
C13: 7 | D13: 43 | E13: 2033 | F13: =(($B$4*12))+($B$5) -> 0 | G13: =G12+F13 -> 0 | I13: 600 | J13: 382000 | K13: =((J13-$B$3)*12)+($B$5) -> 4584000 | L13: =L12+K13 -> 29616000 | N13: 650 | O13: 415000 | P13: =((O13-$B$3)*12)+($B$5) -> 4980000 | Q13: =Q12+P13 -> 30768000 | S13: 800 | T13: 493000 | U13: =((T13-$B$3)*12)+($B$5) -> 5916000 | V13: =V12+U13 -> 33804000
C14: 8 | D14: 44 | E14: 2034 | F14: =(($B$4*12))+($B$5) -> 0 | G14: =G13+F14 -> 0 | I14: 650 | J14: 415000 | K14: =((J14-$B$3)*12)+($B$5) -> 4980000 | L14: =L13+K14 -> 34596000 | N14: 700 | O14: 441000 | P14: =((O14-$B$3)*12)+($B$5) -> 5292000 | Q14: =Q13+P14 -> 36060000 | S14: 850 | T14: 520000 | U14: =((T14-$B$3)*12)+($B$5) -> 6240000 | V14: =V13+U14 -> 40044000
C15: 9 | D15: 45 | E15: 2035 | F15: =(($B$4*12))+($B$5) -> 0 | G15: =G14+F15 -> 0 | I15: 650 | J15: 415000 | K15: =((J15-$B$3)*12)+($B$5) -> 4980000 | L15: =L14+K15 -> 39576000 | N15: 700 | O15: 441000 | P15: =((O15-$B$3)*12)+($B$5) -> 5292000 | Q15: =Q14+P15 -> 41352000 | S15: 900 | T15: 548000 | U15: =((T15-$B$3)*12)+($B$5) -> 6576000 | V15: =V14+U15 -> 46620000
C16: 10 | D16: 46 | E16: 2036 | F16: =(($B$4*12))+($B$5) -> 0 | G16: =G15+F16 -> 0 | I16: 650 | J16: 415000 | K16: =((J16-$B$3)*12)+($B$5) -> 4980000 | L16: =L15+K16 -> 44556000 | N16: 750 | O16: 468000 | P16: =((O16-$B$3)*12)+($B$5) -> 5616000 | Q16: =Q15+P16 -> 46968000 | S16: 950 | T16: 582000 | U16: =((T16-$B$3)*12)+($B$5) -> 6984000 | V16: =V15+U16 -> 53604000
C17: 11 | D17: 47 | E17: 2037 | F17: =(($B$4*12))+($B$5) -> 0 | G17: =G16+F17 -> 0 | I17: 700 | J17: 441000 | K17: =((J17-$B$3)*12)+($B$5) -> 5292000 | L17: =L16+K17 -> 49848000 | N17: 750 | O17: 468000 | P17: =((O17-$B$3)*12)+($B$5) -> 5616000 | Q17: =Q16+P17 -> 52584000 | S17: 1000 | T17: 608000 | U17: =((T17-$B$3)*12)+($B$5) -> 7296000 | V17: =V16+U17 -> 60900000
C18: 12 | D18: 48 | E18: 2038 | F18: =(($B$4*12))+($B$5) -> 0 | G18: =G17+F18 -> 0 | I18: 700 | J18: 441000 | K18: =((J18-$B$3)*12)+($B$5) -> 5292000 | L18: =L17+K18 -> 55140000 | N18: 800 | O18: 493000 | P18: =((O18-$B$3)*12)+($B$5) -> 5916000 | Q18: =Q17+P18 -> 58500000 | S18: 1000 | T18: 608000 | U18: =((T18-$B$3)*12)+($B$5) -> 7296000 | V18: =V17+U18 -> 68196000
C19: 13 | D19: 49 | E19: 2039 | F19: =(($B$4*12))+($B$5) -> 0 | G19: =G18+F19 -> 0 | I19: 700 | J19: 441000 | K19: =((J19-$B$3)*12)+($B$5) -> 5292000 | L19: =L18+K19 -> 60432000 | N19: 800 | O19: 493000 | P19: =((O19-$B$3)*12)+($B$5) -> 5916000 | Q19: =Q18+P19 -> 64416000 | S19: 1000 | T19: 608000 | U19: =((T19-$B$3)*12)+($B$5) -> 7296000 | V19: =V18+U19 -> 75492000
... C24: 18 | D24: 54 | E24: 2044 | F24: =(($B$4*12))+($B$5) -> 0 | G24: =G23+F24 -> 0 | I24: 800 | J24: 493000 | K24: =((J24-$B$3)*12)+($B$5) -> 5916000 | L24: =L23+K24 -> 89112000 | N24: 950 | O24: 582000 | P24: =((O24-$B$3)*12)+($B$5) -> 6984000 | Q24: =Q23+P24 -> 97032000 | S24: 1000 | T24: 608000 | U24: =((T24-$B$3)*12)+($B$5) -> 7296000 | V24: =V23+U24 -> 111972000
B25: 정년 | C25: 19 | D25: 55 | E25: 2045 | F25: =(($B$4*12))+($B$5) -> 0 | G25: =G24+F25 -> 0 | I25: 800 | J25: 493000 | K25: =((J25-$B$3)*12)+($B$5) -> 5916000 | L25: =L24+K25 -> 95028000 | N25: 950 | O25: 582000 | P25: =((O25-$B$3)*12)+($B$5) -> 6984000 | Q25: =Q24+P25 -> 104016000 | S25: 1000 | T25: 608000 | U25: =((T25-$B$3)*12)+($B$5) -> 7296000 | V25: =V24+U25 -> 119268000
C26: 20 | D26: 56 | E26: 2046 | F26: =(($B$4*12))+($B$5) -> 0 | G26: =G25+F26 -> 0 | I26: 850 | J26: 520000 | K26: =((J26-$B$3)*12)+($B$5) -> 6240000 | L26: =L25+K26 -> 101268000 | N26: 1000 | O26: 608000 | P26: =((O26-$B$3)*12)+($B$5) -> 7296000 | Q26: =Q25+P26 -> 111312000 | S26: 1000 | T26: 608000 | U26: =((T26-$B$3)*12)+($B$5) -> 7296000 | V26: =V25+U26 -> 126564000
C27: 21 | D27: 57 | E27: 2047 | F27: =(($B$4*12))+($B$5) -> 0 | G27: =G26+F27 -> 0 | I27: 850 | J27: 520000 | K27: =((J27-$B$3)*12)+($B$5) -> 6240000 | L27: =L26+K27 -> 107508000 | N27: 1000 | O27: 608000 | P27: =((O27-$B$3)*12)+($B$5) -> 7296000 | Q27: =Q26+P27 -> 118608000 | S27: 1000 | T27: 608000 | U27: =((T27-$B$3)*12)+($B$5) -> 7296000 | V27: =V26+U27 -> 133860000
C28: 22 | D28: 58 | E28: 2048 | F28: =(($B$4*12))+($B$5) -> 0 | G28: =G27+F28 -> 0 | I28: 850 | J28: 520000 | K28: =((J28-$B$3)*12)+($B$5) -> 6240000 | L28: =L27+K28 -> 113748000 | N28: 900 | O28: 548000 | P28: =((O28-$B$3)*12)+($B$5) -> 6576000 | Q28: =Q27+P28 -> 125184000 | S28: 900 | T28: 548000 | U28: =((T28-$B$3)*12)+($B$5) -> 6576000 | V28: =V27+U28 -> 140436000
C29: 23 | D29: 59 | E29: 2049 | F29: =(($B$4*12))+($B$5) -> 0 | G29: =G28+F29 -> 0 | I29: 900 | J29: 548000 | K29: =((J29-$B$3)*12)+($B$5) -> 6576000 | L29: =L28+K29 -> 120324000 | N29: 900 | O29: 548000 | P29: =((O29-$B$3)*12)+($B$5) -> 6576000 | Q29: =Q28+P29 -> 131760000 | S29: 900 | T29: 548000 | U29: =((T29-$B$3)*12)+($B$5) -> 6576000 | V29: =V28+U29 -> 147012000
C30: 24 | D30: 60 | E30: 2050 | F30: =(($B$4*12))+($B$5) -> 0 | G30: =G29+F30 -> 0 | I30: 900 | J30: 548000 | K30: =((J30-$B$3)*12)+($B$5) -> 6576000 | L30: =L29+K30 -> 126900000 | N30: 850 | O30: 520000 | P30: =((O30-$B$3)*12)+($B$5) -> 6240000 | Q30: =Q29+P30 -> 138000000 | S30: 850 | T30: 520000 | U30: =((T30-$B$3)*12)+($B$5) -> 6240000 | V30: =V29+U30 -> 153252000
C31: 25 | D31: 61 | E31: 2051 | F31: =(($B$4*12))+($B$5) -> 0 | G31: =G30+F31 -> 0 | I31: 900 | J31: 548000 | K31: =((J31-$B$3)*12)+($B$5) -> 6576000 | L31: =L30+K31 -> 133476000 | N31: 850 | O31: 520000 | P31: =((O31-$B$3)*12)+($B$5) -> 6240000 | Q31: =Q30+P31 -> 144240000 | S31: 850 | T31: 520000 | U31: =((T31-$B$3)*12)+($B$5) -> 6240000 | V31: =V30+U31 -> 159492000
C32: 26 | D32: 62 | E32: 2052 | F32: =(($B$4*12))+($B$5) -> 0 | G32: =G31+F32 -> 0 | I32: 950 | J32: 582000 | K32: =((J32-$B$3)*12)+($B$5) -> 6984000 | L32: =L31+K32 -> 140460000 | N32: 700 | O32: 441000 | P32: =((O32-$B$3)*12)+($B$5) -> 5292000 | Q32: =Q31+P32 -> 149532000 | S32: 700 | T32: 441000 | U32: =((T32-$B$3)*12)+($B$5) -> 5292000 | V32: =V31+U32 -> 164784000
C33: 27 | D33: 63 | E33: 2053 | F33: =(($B$4*12))+($B$5) -> 0 | G33: =G32+F33 -> 0 | I33: 950 | J33: 582000 | K33: =((J33-$B$3)*12)+($B$5) -> 6984000 | L33: =L32+K33 -> 147444000 | N33: 700 | O33: 441000 | P33: =((O33-$B$3)*12)+($B$5) -> 5292000 | Q33: =Q32+P33 -> 154824000 | S33: 700 | T33: 441000 | U33: =((T33-$B$3)*12)+($B$5) -> 5292000 | V33: =V32+U33 -> 170076000
C34: 28 | D34: 64 | E34: 2054 | F34: =(($B$4*12))+($B$5) -> 0 | G34: =G33+F34 -> 0 | I34: 950 | J34: 582000 | K34: =((J34-$B$3)*12)+($B$5) -> 6984000 | L34: =L33+K34 -> 154428000 | N34: 600 | O34: 382000 | P34: =((O34-$B$3)*12)+($B$5) -> 4584000 | Q34: =Q33+P34 -> 159408000 | S34: 600 | T34: 382000 | U34: =((T34-$B$3)*12)+($B$5) -> 4584000 | V34: =V33+U34 -> 174660000
C35: 29 | D35: 65 | E35: 2055 | F35: =(($B$4*12))+($B$5) -> 0 | G35: =G34+F35 -> 0 | I35: 1000 | J35: 608000 | K35: =((J35-$B$3)*12)+($B$5) -> 7296000 | L35: =L34+K35 -> 161724000 | N35: 600 | O35: 382000 | P35: =((O35-$B$3)*12)+($B$5) -> 4584000 | Q35: =Q34+P35 -> 163992000 | S35: 600 | T35: 382000 | U35: =((T35-$B$3)*12)+($B$5) -> 4584000 | V35: =V34+U35 -> 179244000
B36: 조기대출상환 | C36: 30 | D36: 66 | E36: 2056 | F36: =(($B$4*12))+($B$5) -> 0 | G36: =G35+F36 -> 0 | I36: 1000 | J36: 608000 | K36: =((J36-$B$3)*12)+($B$5) -> 7296000 | L36: =L35+K36 -> 169020000 | N36: 500 | O36: 319200 | P36: =((O36-$B$3)*12)+($B$5) -> 3830400 | Q36: =Q35+P36 -> 167822400 | S36: 500 | T36: 319200 | U36: =((T36-$B$3)*12)+($B$5) -> 3830400 | V36: =V35+U36 -> 183074400
C37: 31 | D37: 67 | E37: 2057 | F37: =(($B$4*12))+($B$5) -> 0 | G37: =G36+F37 -> 0 | I37: 1000 | J37: 608000 | K37: =((J37-$B$3)*12)+($B$5) -> 7296000 | L37: =L36+K37 -> 176316000 | N37: 500 | O37: 319200 | P37: =((O37-$B$3)*12)+($B$5) -> 3830400 | Q37: =Q36+P37 -> 171652800 | S37: 500 | T37: 319200 | U37: =((T37-$B$3)*12)+($B$5) -> 3830400 | V37: =V36+U37 -> 186904800
C38: 32 | D38: 68 | E38: 2058 | F38: =(($B$4*12))+($B$5) -> 0 | G38: =G37+F38 -> 0 | I38: 1000 | J38: 608000 | K38: =((J38-$B$3)*12)+($B$5) -> 7296000 | L38: =L37+K38 -> 183612000 | N38: 500 | O38: 319200 | P38: =((O38-$B$3)*12)+($B$5) -> 3830400 | Q38: =Q37+P38 -> 175483200 | S38: 500 | T38: 319200 | U38: =((T38-$B$3)*12)+($B$5) -> 3830400 | V38: =V37+U38 -> 190735200
C39: 33 | D39: 69 | E39: 2059 | F39: =(($B$4*12))+($B$5) -> 0 | G39: =G38+F39 -> 0 | I39: 1000 | J39: 608000 | K39: =((J39-$B$3)*12)+($B$5) -> 7296000 | L39: =L38+K39 -> 190908000 | N39: 500 | O39: 319200 | P39: =((O39-$B$3)*12)+($B$5) -> 3830400 | Q39: =Q38+P39 -> 179313600 | S39: 500 | T39: 319200 | U39: =((T39-$B$3)*12)+($B$5) -> 3830400 | V39: =V38+U39 -> 194565600
C40: 34 | D40: 70 | E40: 2060 | F40: =(($B$4*12))+($B$5) -> 0 | G40: =G39+F40 -> 0 | I40: 1000 | J40: 608000 | K40: =((J40-$B$3)*12)+($B$5) -> 7296000 | L40: =L39+K40 -> 198204000 | N40: 500 | O40: 319200 | P40: =((O40-$B$3)*12)+($B$5) -> 3830400 | Q40: =Q39+P40 -> 183144000 | S40: 500 | T40: 319200 | U40: =((T40-$B$3)*12)+($B$5) -> 3830400 | V40: =V39+U40 -> 198396000
B41: 대출상환 | C41: 35 | D41: 71 | E41: 2061 | F41: =(($B$4*12))+($B$5) -> 0 | G41: =G40+F41 -> 0 | I41: 1000 | J41: 608000 | K41: =((J41-$B$3)*12)+($B$5) -> 7296000 | L41: =L40+K41 -> 205500000 | N41: 500 | O41: 319200 | P41: =((O41-$B$3)*12)+($B$5) -> 3830400 | Q41: =Q40+P41 -> 186974400 | S41: 500 | T41: 319200 | U41: =((T41-$B$3)*12)+($B$5) -> 3830400 | V41: =V40+U41 -> 202226400
C42: 36 | D42: 72 | E42: 2062 | F42: =(($B$4*12))+($B$5) -> 0 | G42: =G41+F42 -> 0 | I42: 1000 | J42: 608000 | K42: =((J42-$B$3)*12)+($B$5) -> 7296000 | L42: =L41+K42 -> 212796000 | N42: 500 | O42: 319200 | P42: =((O42-$B$3)*12)+($B$5) -> 3830400 | Q42: =Q41+P42 -> 190804800 | S42: 500 | T42: 319200 | U42: =((T42-$B$3)*12)+($B$5) -> 3830400 | V42: =V41+U42 -> 206056800
C43: 37 | D43: 73 | E43: 2063 | F43: =(($B$4*12))+($B$5) -> 0 | G43: =G42+F43 -> 0 | I43: 1000 | J43: 608000 | K43: =((J43-$B$3)*12)+($B$5) -> 7296000 | L43: =L42+K43 -> 220092000 | N43: 500 | O43: 319200 | P43: =((O43-$B$3)*12)+($B$5) -> 3830400 | Q43: =Q42+P43 -> 194635200 | S43: 500 | T43: 319200 | U43: =((T43-$B$3)*12)+($B$5) -> 3830400 | V43: =V42+U43 -> 209887200
C44: 38 | D44: 74 | E44: 2064 | F44: =(($B$4*12))+($B$5) -> 0 | G44: =G43+F44 -> 0 | I44: 1000 | J44: 608000 | K44: =((J44-$B$3)*12)+($B$5) -> 7296000 | L44: =L43+K44 -> 227388000 | N44: 500 | O44: 319200 | P44: =((O44-$B$3)*12)+($B$5) -> 3830400 | Q44: =Q43+P44 -> 198465600 | S44: 500 | T44: 319200 | U44: =((T44-$B$3)*12)+($B$5) -> 3830400 | V44: =V43+U44 -> 213717600
...

Sheet 2026년달력
A1: 2026 | B1: 오늘 | H1: 예상수입 | I1: 0 | O1: 月 | P1: 1 | Q1: 2 | R1: 3 | S1: 4 | T1: 5 | U1: 6 | V1: 7 | W1: 8 | X1: 9 | Y1: 10 | Z1: 11 | AA1: 12
B2: =TODAY() -> 46168 | O2: =참조!$D$2 -> 休 | P2: =COUNTIFS($B$7:$B$371,">="&DATE($A$1,P$1,1),$B$7:$B$371,"<"&DATE($A$1,P$1+1,1),$G$7:$G$371,참조!$D$2) -> 12 | Q2: =COUNTIFS($B$7:$B$371,">="&DATE($A$1,Q$1,1),$B$7:$B$371,"<"&DATE($A$1,Q$1+1,1),$G$7:$G$371,참조!$D$2) -> 10 | R2: =COUNTIFS($B$7:$B$371,">="&DATE($A$1,R$1,1),$B$7:$B$371,"<"&DATE($A$1,R$1+1,1),$G$7:$G$371,참조!$D$2) -> 10 | S2: =COUNTIFS($B$7:$B$371,">="&DATE($A$1,S$1,1),$B$7:$B$371,"<"&DATE($A$1,S$1+1,1),$G$7:$G$371,참조!$D$2) -> 9 | T2: =COUNTIFS($B$7:$B$371,">="&DATE($A$1,T$1,1),$B$7:$B$371,"<"&DATE($A$1,T$1+1,1),$G$7:$G$371,참조!$D$2) -> 13 | U2: =COUNTIFS($B$7:$B$371,">="&DATE($A$1,U$1,1),$B$7:$B$371,"<"&DATE($A$1,U$1+1,1),$G$7:$G$371,참조!$D$2) -> 8 | V2: =COUNTIFS($B$7:$B$371,">="&DATE($A$1,V$1,1),$B$7:$B$371,"<"&DATE($A$1,V$1+1,1),$G$7:$G$371,참조!$D$2) -> 9 | W2: =COUNTIFS($B$7:$B$371,">="&DATE($A$1,W$1,1),$B$7:$B$371,"<"&DATE($A$1,W$1+1,1),$G$7:$G$371,참조!$D$2) -> 11 | ... AA2: =COUNTIFS($B$7:$B$371,">="&DATE($A$1,AA$1,1),$B$7:$B$371,"<"&DATE($A$1,AA$1+1,1),$G$7:$G$371,참조!$D$2) -> 12
O3: =참조!$D$3 -> 勤 | P3: =COUNTIFS($B$7:$B$371,">="&DATE($A$1,P$1,1),$B$7:$B$371,"<"&DATE($A$1,P$1+1,1),$G$7:$G$371,참조!$D$3) -> 19 | Q3: =COUNTIFS($B$7:$B$371,">="&DATE($A$1,Q$1,1),$B$7:$B$371,"<"&DATE($A$1,Q$1+1,1),$G$7:$G$371,참조!$D$3) -> 18 | R3: =COUNTIFS($B$7:$B$371,">="&DATE($A$1,R$1,1),$B$7:$B$371,"<"&DATE($A$1,R$1+1,1),$G$7:$G$371,참조!$D$3) -> 21 | S3: =COUNTIFS($B$7:$B$371,">="&DATE($A$1,S$1,1),$B$7:$B$371,"<"&DATE($A$1,S$1+1,1),$G$7:$G$371,참조!$D$3) -> 21 | T3: =COUNTIFS($B$7:$B$371,">="&DATE($A$1,T$1,1),$B$7:$B$371,"<"&DATE($A$1,T$1+1,1),$G$7:$G$371,참조!$D$3) -> 18 | U3: =COUNTIFS($B$7:$B$371,">="&DATE($A$1,U$1,1),$B$7:$B$371,"<"&DATE($A$1,U$1+1,1),$G$7:$G$371,참조!$D$3) -> 22 | V3: =COUNTIFS($B$7:$B$371,">="&DATE($A$1,V$1,1),$B$7:$B$371,"<"&DATE($A$1,V$1+1,1),$G$7:$G$371,참조!$D$3) -> 22 | W3: =COUNTIFS($B$7:$B$371,">="&DATE($A$1,W$1,1),$B$7:$B$371,"<"&DATE($A$1,W$1+1,1),$G$7:$G$371,참조!$D$3) -> 20 | ... AA3: =COUNTIFS($B$7:$B$371,">="&DATE($A$1,AA$1,1),$B$7:$B$371,"<"&DATE($A$1,AA$1+1,1),$G$7:$G$371,참조!$D$3) -> 19
O4: 지출 | P4: =SUMIFS($L$7:$L$371,$B$7:$B$371,">="&DATE($A$1,P$1,1),$B$7:$B$371,"<"&DATE($A$1,P$1+1,1)) -> 0 | Q4: =SUMIFS($L$7:$L$371,$B$7:$B$371,">="&DATE($A$1,Q$1,1),$B$7:$B$371,"<"&DATE($A$1,Q$1+1,1)) -> 0 | R4: =SUMIFS($L$7:$L$371,$B$7:$B$371,">="&DATE($A$1,R$1,1),$B$7:$B$371,"<"&DATE($A$1,R$1+1,1)) -> 0 | S4: =SUMIFS($L$7:$L$371,$B$7:$B$371,">="&DATE($A$1,S$1,1),$B$7:$B$371,"<"&DATE($A$1,S$1+1,1)) -> 0 | T4: =SUMIFS($L$7:$L$371,$B$7:$B$371,">="&DATE($A$1,T$1,1),$B$7:$B$371,"<"&DATE($A$1,T$1+1,1)) -> 13000 | U4: =SUMIFS($L$7:$L$371,$B$7:$B$371,">="&DATE($A$1,U$1,1),$B$7:$B$371,"<"&DATE($A$1,U$1+1,1)) -> 62000 | V4: =SUMIFS($L$7:$L$371,$B$7:$B$371,">="&DATE($A$1,V$1,1),$B$7:$B$371,"<"&DATE($A$1,V$1+1,1)) -> 67000 | W4: =SUMIFS($L$7:$L$371,$B$7:$B$371,">="&DATE($A$1,W$1,1),$B$7:$B$371,"<"&DATE($A$1,W$1+1,1)) -> 75000 | ... AA4: =SUMIFS($L$7:$L$371,$B$7:$B$371,">="&DATE($A$1,AA$1,1),$B$7:$B$371,"<"&DATE($A$1,AA$1+1,1)) -> 79000 | AB4: =SUM(P4:Z4) -> 436000
O5: 수입 | P5: =$I$1-P$4 -> 0 | Q5: =$I$1-Q$4 -> 0 | R5: =$I$1-R$4 -> 0 | S5: =$I$1-S$4 -> 0 | T5: =$I$1-T$4 -> -13000 | U5: =$I$1-U$4 -> -62000 | V5: =$I$1-V$4 -> -67000 | W5: =$I$1-W$4 -> -75000 | ... AA5: =$I$1-AA$4 -> -79000 | AB5: =SUM(P5:AA5) -> -515000
B6: 날짜 | C6: 월 | D6: 일 | E6: 요일(수) | F6: 요일 | H6: 예상지출 | I6: 실지출 | J6: 실수입 | K6: 지출차액(지출-수입) | L6: 계산지출 | M6: 예상외수익(예상지출-지출차액)
B7: =DATE($A$1,C7,D7) -> 46023 | C7: 1 | D7: 1 | E7: =WEEKDAY(B7) -> 5 | F7: =IF($E7=참조!$B$2,참조!$C$2,IF($E7=참조!$B$3,참조!$C$3,IF($E7=참조!$B$4,참조!$C$4,IF($E7=참조!$B$5,참조!$C$5,IF($E7=참조!$B$6,참조!$C$6,IF($E7=참조!$B$7,참조!$C$7,IF($E7=참조!$B$8,참조!$C$8,""))))))) -> 木 | G7: =IF($F7=참조!$C$2,참조!$D$2,IF($F7=참조!$C$8,참조!$D$2,IF(COUNTIF('2026년휴일'!$B:$B,$B7)>0,참조!$D$2,참조!$D$3))) -> 休 | H7: =IF($G7=참조!$D$3,참조!$E$3,참조!$E$2) -> 5000 | I7: =SUMIFS(지출기록_1월!$H$3:$H$312,지출기록_1월!$E$3:$E$312,B7,지출기록_1월!$F$3:$F$312,참조!$F$2) -> 0 | J7: =SUMIFS(지출기록_1월!$H$3:$H$312,지출기록_1월!$E$3:$E$312,B7,지출기록_1월!$F$3:$F$312,참조!$F$3) -> 0 | K7: =I7-J7 -> 0 | L7: =IF(B7>$B$2,H7,K7) -> 0 | M7: =$H7-$K7 -> 5000
B8: =DATE($A$1,C8,D8) -> 46024 | C8: 1 | D8: 2 | E8: =WEEKDAY(B8) -> 6 | F8: =IF($E8=참조!$B$2,참조!$C$2,IF($E8=참조!$B$3,참조!$C$3,IF($E8=참조!$B$4,참조!$C$4,IF($E8=참조!$B$5,참조!$C$5,IF($E8=참조!$B$6,참조!$C$6,IF($E8=참조!$B$7,참조!$C$7,IF($E8=참조!$B$8,참조!$C$8,""))))))) -> 金 | G8: =IF($F8=참조!$C$2,참조!$D$2,IF($F8=참조!$C$8,참조!$D$2,IF(COUNTIF('2026년휴일'!$B:$B,$B8)>0,참조!$D$2,참조!$D$3))) -> 休 | H8: =IF($G8=참조!$D$3,참조!$E$3,참조!$E$2) -> 5000 | I8: =SUMIFS(지출기록_1월!$H$3:$H$312,지출기록_1월!$E$3:$E$312,B8,지출기록_1월!$F$3:$F$312,참조!$F$2) -> 0 | J8: =SUMIFS(지출기록_1월!$H$3:$H$312,지출기록_1월!$E$3:$E$312,B8,지출기록_1월!$F$3:$F$312,참조!$F$3) -> 0 | K8: =I8-J8 -> 0 | L8: =IF(B8>$B$2,H8,K8) -> 0 | M8: =$H8-$K8 -> 5000
B9: =DATE($A$1,C9,D9) -> 46025 | C9: 1 | D9: 3 | E9: =WEEKDAY(B9) -> 7 | F9: =IF($E9=참조!$B$2,참조!$C$2,IF($E9=참조!$B$3,참조!$C$3,IF($E9=참조!$B$4,참조!$C$4,IF($E9=참조!$B$5,참조!$C$5,IF($E9=참조!$B$6,참조!$C$6,IF($E9=참조!$B$7,참조!$C$7,IF($E9=참조!$B$8,참조!$C$8,""))))))) -> 土 | G9: =IF($F9=참조!$C$2,참조!$D$2,IF($F9=참조!$C$8,참조!$D$2,IF(COUNTIF('2026년휴일'!$B:$B,$B9)>0,참조!$D$2,참조!$D$3))) -> 休 | H9: =IF($G9=참조!$D$3,참조!$E$3,참조!$E$2) -> 5000 | I9: =SUMIFS(지출기록_1월!$H$3:$H$312,지출기록_1월!$E$3:$E$312,B9,지출기록_1월!$F$3:$F$312,참조!$F$2) -> 0 | J9: =SUMIFS(지출기록_1월!$H$3:$H$312,지출기록_1월!$E$3:$E$312,B9,지출기록_1월!$F$3:$F$312,참조!$F$3) -> 0 | K9: =I9-J9 -> 0 | L9: =IF(B9>$B$2,H9,K9) -> 0 | M9: =$H9-$K9 -> 5000
B10: =DATE($A$1,C10,D10) -> 46026 | C10: 1 | D10: 4 | E10: =WEEKDAY(B10) -> 1 | F10: =IF($E10=참조!$B$2,참조!$C$2,IF($E10=참조!$B$3,참조!$C$3,IF($E10=참조!$B$4,참조!$C$4,IF($E10=참조!$B$5,참조!$C$5,IF($E10=참조!$B$6,참조!$C$6,IF($E10=참조!$B$7,참조!$C$7,IF($E10=참조!$B$8,참조!$C$8,""))))))) -> 日 | G10: =IF($F10=참조!$C$2,참조!$D$2,IF($F10=참조!$C$8,참조!$D$2,IF(COUNTIF('2026년휴일'!$B:$B,$B10)>0,참조!$D$2,참조!$D$3))) -> 休 | H10: =IF($G10=참조!$D$3,참조!$E$3,참조!$E$2) -> 5000 | I10: =SUMIFS(지출기록_1월!$H$3:$H$312,지출기록_1월!$E$3:$E$312,B10,지출기록_1월!$F$3:$F$312,참조!$F$2) -> 0 | J10: =SUMIFS(지출기록_1월!$H$3:$H$312,지출기록_1월!$E$3:$E$312,B10,지출기록_1월!$F$3:$F$312,참조!$F$3) -> 0 | K10: =I10-J10 -> 0 | L10: =IF(B10>$B$2,H10,K10) -> 0 | M10: =$H10-$K10 -> 5000
B11: =DATE($A$1,C11,D11) -> 46027 | C11: 1 | D11: 5 | E11: =WEEKDAY(B11) -> 2 | F11: =IF($E11=참조!$B$2,참조!$C$2,IF($E11=참조!$B$3,참조!$C$3,IF($E11=참조!$B$4,참조!$C$4,IF($E11=참조!$B$5,참조!$C$5,IF($E11=참조!$B$6,참조!$C$6,IF($E11=참조!$B$7,참조!$C$7,IF($E11=참조!$B$8,참조!$C$8,""))))))) -> 月 | G11: =IF($F11=참조!$C$2,참조!$D$2,IF($F11=참조!$C$8,참조!$D$2,IF(COUNTIF('2026년휴일'!$B:$B,$B11)>0,참조!$D$2,참조!$D$3))) -> 勤 | H11: =IF($G11=참조!$D$3,참조!$E$3,참조!$E$2) -> 1000 | I11: =SUMIFS(지출기록_1월!$H$3:$H$312,지출기록_1월!$E$3:$E$312,B11,지출기록_1월!$F$3:$F$312,참조!$F$2) -> 0 | J11: =SUMIFS(지출기록_1월!$H$3:$H$312,지출기록_1월!$E$3:$E$312,B11,지출기록_1월!$F$3:$F$312,참조!$F$3) -> 0 | K11: =I11-J11 -> 0 | L11: =IF(B11>$B$2,H11,K11) -> 0 | M11: =$H11-$K11 -> 1000
B12: =DATE($A$1,C12,D12) -> 46028 | C12: 1 | D12: 6 | E12: =WEEKDAY(B12) -> 3 | F12: =IF($E12=참조!$B$2,참조!$C$2,IF($E12=참조!$B$3,참조!$C$3,IF($E12=참조!$B$4,참조!$C$4,IF($E12=참조!$B$5,참조!$C$5,IF($E12=참조!$B$6,참조!$C$6,IF($E12=참조!$B$7,참조!$C$7,IF($E12=참조!$B$8,참조!$C$8,""))))))) -> 火 | G12: =IF($F12=참조!$C$2,참조!$D$2,IF($F12=참조!$C$8,참조!$D$2,IF(COUNTIF('2026년휴일'!$B:$B,$B12)>0,참조!$D$2,참조!$D$3))) -> 勤 | H12: =IF($G12=참조!$D$3,참조!$E$3,참조!$E$2) -> 1000 | I12: =SUMIFS(지출기록_1월!$H$3:$H$312,지출기록_1월!$E$3:$E$312,B12,지출기록_1월!$F$3:$F$312,참조!$F$2) -> 0 | J12: =SUMIFS(지출기록_1월!$H$3:$H$312,지출기록_1월!$E$3:$E$312,B12,지출기록_1월!$F$3:$F$312,참조!$F$3) -> 0 | K12: =I12-J12 -> 0 | L12: =IF(B12>$B$2,H12,K12) -> 0 | M12: =$H12-$K12 -> 1000
B13: =DATE($A$1,C13,D13) -> 46029 | C13: 1 | D13: 7 | E13: =WEEKDAY(B13) -> 4 | F13: =IF($E13=참조!$B$2,참조!$C$2,IF($E13=참조!$B$3,참조!$C$3,IF($E13=참조!$B$4,참조!$C$4,IF($E13=참조!$B$5,참조!$C$5,IF($E13=참조!$B$6,참조!$C$6,IF($E13=참조!$B$7,참조!$C$7,IF($E13=참조!$B$8,참조!$C$8,""))))))) -> 水 | G13: =IF($F13=참조!$C$2,참조!$D$2,IF($F13=참조!$C$8,참조!$D$2,IF(COUNTIF('2026년휴일'!$B:$B,$B13)>0,참조!$D$2,참조!$D$3))) -> 勤 | H13: =IF($G13=참조!$D$3,참조!$E$3,참조!$E$2) -> 1000 | I13: =SUMIFS(지출기록_1월!$H$3:$H$312,지출기록_1월!$E$3:$E$312,B13,지출기록_1월!$F$3:$F$312,참조!$F$2) -> 0 | J13: =SUMIFS(지출기록_1월!$H$3:$H$312,지출기록_1월!$E$3:$E$312,B13,지출기록_1월!$F$3:$F$312,참조!$F$3) -> 0 | K13: =I13-J13 -> 0 | L13: =IF(B13>$B$2,H13,K13) -> 0 | M13: =$H13-$K13 -> 1000
B14: =DATE($A$1,C14,D14) -> 46030 | C14: 1 | D14: 8 | E14: =WEEKDAY(B14) -> 5 | F14: =IF($E14=참조!$B$2,참조!$C$2,IF($E14=참조!$B$3,참조!$C$3,IF($E14=참조!$B$4,참조!$C$4,IF($E14=참조!$B$5,참조!$C$5,IF($E14=참조!$B$6,참조!$C$6,IF($E14=참조!$B$7,참조!$C$7,IF($E14=참조!$B$8,참조!$C$8,""))))))) -> 木 | G14: =IF($F14=참조!$C$2,참조!$D$2,IF($F14=참조!$C$8,참조!$D$2,IF(COUNTIF('2026년휴일'!$B:$B,$B14)>0,참조!$D$2,참조!$D$3))) -> 勤 | H14: =IF($G14=참조!$D$3,참조!$E$3,참조!$E$2) -> 1000 | I14: =SUMIFS(지출기록_1월!$H$3:$H$312,지출기록_1월!$E$3:$E$312,B14,지출기록_1월!$F$3:$F$312,참조!$F$2) -> 0 | J14: =SUMIFS(지출기록_1월!$H$3:$H$312,지출기록_1월!$E$3:$E$312,B14,지출기록_1월!$F$3:$F$312,참조!$F$3) -> 0 | K14: =I14-J14 -> 0 | L14: =IF(B14>$B$2,H14,K14) -> 0 | M14: =$H14-$K14 -> 1000
B15: =DATE($A$1,C15,D15) -> 46031 | C15: 1 | D15: 9 | E15: =WEEKDAY(B15) -> 6 | F15: =IF($E15=참조!$B$2,참조!$C$2,IF($E15=참조!$B$3,참조!$C$3,IF($E15=참조!$B$4,참조!$C$4,IF($E15=참조!$B$5,참조!$C$5,IF($E15=참조!$B$6,참조!$C$6,IF($E15=참조!$B$7,참조!$C$7,IF($E15=참조!$B$8,참조!$C$8,""))))))) -> 金 | G15: =IF($F15=참조!$C$2,참조!$D$2,IF($F15=참조!$C$8,참조!$D$2,IF(COUNTIF('2026년휴일'!$B:$B,$B15)>0,참조!$D$2,참조!$D$3))) -> 勤 | H15: =IF($G15=참조!$D$3,참조!$E$3,참조!$E$2) -> 1000 | I15: =SUMIFS(지출기록_1월!$H$3:$H$312,지출기록_1월!$E$3:$E$312,B15,지출기록_1월!$F$3:$F$312,참조!$F$2) -> 0 | J15: =SUMIFS(지출기록_1월!$H$3:$H$312,지출기록_1월!$E$3:$E$312,B15,지출기록_1월!$F$3:$F$312,참조!$F$3) -> 0 | K15: =I15-J15 -> 0 | L15: =IF(B15>$B$2,H15,K15) -> 0 | M15: =$H15-$K15 -> 1000
B16: =DATE($A$1,C16,D16) -> 46032 | C16: 1 | D16: 10 | E16: =WEEKDAY(B16) -> 7 | F16: =IF($E16=참조!$B$2,참조!$C$2,IF($E16=참조!$B$3,참조!$C$3,IF($E16=참조!$B$4,참조!$C$4,IF($E16=참조!$B$5,참조!$C$5,IF($E16=참조!$B$6,참조!$C$6,IF($E16=참조!$B$7,참조!$C$7,IF($E16=참조!$B$8,참조!$C$8,""))))))) -> 土 | G16: =IF($F16=참조!$C$2,참조!$D$2,IF($F16=참조!$C$8,참조!$D$2,IF(COUNTIF('2026년휴일'!$B:$B,$B16)>0,참조!$D$2,참조!$D$3))) -> 休 | H16: =IF($G16=참조!$D$3,참조!$E$3,참조!$E$2) -> 5000 | I16: =SUMIFS(지출기록_1월!$H$3:$H$312,지출기록_1월!$E$3:$E$312,B16,지출기록_1월!$F$3:$F$312,참조!$F$2) -> 0 | J16: =SUMIFS(지출기록_1월!$H$3:$H$312,지출기록_1월!$E$3:$E$312,B16,지출기록_1월!$F$3:$F$312,참조!$F$3) -> 0 | K16: =I16-J16 -> 0 | L16: =IF(B16>$B$2,H16,K16) -> 0 | M16: =$H16-$K16 -> 5000
B17: =DATE($A$1,C17,D17) -> 46033 | C17: 1 | D17: 11 | E17: =WEEKDAY(B17) -> 1 | F17: =IF($E17=참조!$B$2,참조!$C$2,IF($E17=참조!$B$3,참조!$C$3,IF($E17=참조!$B$4,참조!$C$4,IF($E17=참조!$B$5,참조!$C$5,IF($E17=참조!$B$6,참조!$C$6,IF($E17=참조!$B$7,참조!$C$7,IF($E17=참조!$B$8,참조!$C$8,""))))))) -> 日 | G17: =IF($F17=참조!$C$2,참조!$D$2,IF($F17=참조!$C$8,참조!$D$2,IF(COUNTIF('2026년휴일'!$B:$B,$B17)>0,참조!$D$2,참조!$D$3))) -> 休 | H17: =IF($G17=참조!$D$3,참조!$E$3,참조!$E$2) -> 5000 | I17: =SUMIFS(지출기록_1월!$H$3:$H$312,지출기록_1월!$E$3:$E$312,B17,지출기록_1월!$F$3:$F$312,참조!$F$2) -> 0 | J17: =SUMIFS(지출기록_1월!$H$3:$H$312,지출기록_1월!$E$3:$E$312,B17,지출기록_1월!$F$3:$F$312,참조!$F$3) -> 0 | K17: =I17-J17 -> 0 | L17: =IF(B17>$B$2,H17,K17) -> 0 | M17: =$H17-$K17 -> 5000
B18: =DATE($A$1,C18,D18) -> 46034 | C18: 1 | D18: 12 | E18: =WEEKDAY(B18) -> 2 | F18: =IF($E18=참조!$B$2,참조!$C$2,IF($E18=참조!$B$3,참조!$C$3,IF($E18=참조!$B$4,참조!$C$4,IF($E18=참조!$B$5,참조!$C$5,IF($E18=참조!$B$6,참조!$C$6,IF($E18=참조!$B$7,참조!$C$7,IF($E18=참조!$B$8,참조!$C$8,""))))))) -> 月 | G18: =IF($F18=참조!$C$2,참조!$D$2,IF($F18=참조!$C$8,참조!$D$2,IF(COUNTIF('2026년휴일'!$B:$B,$B18)>0,참조!$D$2,참조!$D$3))) -> 休 | H18: =IF($G18=참조!$D$3,참조!$E$3,참조!$E$2) -> 5000 | I18: =SUMIFS(지출기록_1월!$H$3:$H$312,지출기록_1월!$E$3:$E$312,B18,지출기록_1월!$F$3:$F$312,참조!$F$2) -> 0 | J18: =SUMIFS(지출기록_1월!$H$3:$H$312,지출기록_1월!$E$3:$E$312,B18,지출기록_1월!$F$3:$F$312,참조!$F$3) -> 0 | K18: =I18-J18 -> 0 | L18: =IF(B18>$B$2,H18,K18) -> 0 | M18: =$H18-$K18 -> 5000
... B37: =DATE($A$1,C37,D37) -> 46053 | C37: 1 | D37: 31 | E37: =WEEKDAY(B37) -> 7 | F37: =IF($E37=참조!$B$2,참조!$C$2,IF($E37=참조!$B$3,참조!$C$3,IF($E37=참조!$B$4,참조!$C$4,IF($E37=참조!$B$5,참조!$C$5,IF($E37=참조!$B$6,참조!$C$6,IF($E37=참조!$B$7,참조!$C$7,IF($E37=참조!$B$8,참조!$C$8,""))))))) -> 土 | G37: =IF($F37=참조!$C$2,참조!$D$2,IF($F37=참조!$C$8,참조!$D$2,IF(COUNTIF('2026년휴일'!$B:$B,$B37)>0,참조!$D$2,참조!$D$3))) -> 休 | H37: =IF($G37=참조!$D$3,참조!$E$3,참조!$E$2) -> 5000 | I37: =SUMIFS(지출기록_1월!$H$3:$H$312,지출기록_1월!$E$3:$E$312,B37,지출기록_1월!$F$3:$F$312,참조!$F$2) -> 0 | J37: =SUMIFS(지출기록_1월!$H$3:$H$312,지출기록_1월!$E$3:$E$312,B37,지출기록_1월!$F$3:$F$312,참조!$F$3) -> 0 | K37: =I37-J37 -> 0 | L37: =IF(B37>$B$2,H37,K37) -> 0 | M37: =$H37-$K37 -> 5000
B38: =DATE($A$1,C38,D38) -> 46054 | C38: 2 | D38: 1 | E38: =WEEKDAY(B38) -> 1 | F38: =IF($E38=참조!$B$2,참조!$C$2,IF($E38=참조!$B$3,참조!$C$3,IF($E38=참조!$B$4,참조!$C$4,IF($E38=참조!$B$5,참조!$C$5,IF($E38=참조!$B$6,참조!$C$6,IF($E38=참조!$B$7,참조!$C$7,IF($E38=참조!$B$8,참조!$C$8,""))))))) -> 日 | G38: =IF($F38=참조!$C$2,참조!$D$2,IF($F38=참조!$C$8,참조!$D$2,IF(COUNTIF('2026년휴일'!$B:$B,$B38)>0,참조!$D$2,참조!$D$3))) -> 休 | H38: =IF($G38=참조!$D$3,참조!$E$3,참조!$E$2) -> 5000 | I38: =SUMIFS(지출기록_2월!$H$3:$H$312,지출기록_2월!$E$3:$E$312,B38,지출기록_2월!$F$3:$F$312,참조!$F$2) -> 0 | J38: =SUMIFS(지출기록_2월!$H$3:$H$312,지출기록_2월!$E$3:$E$312,B38,지출기록_2월!$F$3:$F$312,참조!$F$3) -> 0 | K38: =I38-J38 -> 0 | L38: =IF(B38>$B$2,H38,K38) -> 0 | M38: =$H38-$K38 -> 5000
B39: =DATE($A$1,C39,D39) -> 46055 | C39: 2 | D39: 2 | E39: =WEEKDAY(B39) -> 2 | F39: =IF($E39=참조!$B$2,참조!$C$2,IF($E39=참조!$B$3,참조!$C$3,IF($E39=참조!$B$4,참조!$C$4,IF($E39=참조!$B$5,참조!$C$5,IF($E39=참조!$B$6,참조!$C$6,IF($E39=참조!$B$7,참조!$C$7,IF($E39=참조!$B$8,참조!$C$8,""))))))) -> 月 | G39: =IF($F39=참조!$C$2,참조!$D$2,IF($F39=참조!$C$8,참조!$D$2,IF(COUNTIF('2026년휴일'!$B:$B,$B39)>0,참조!$D$2,참조!$D$3))) -> 勤 | H39: =IF($G39=참조!$D$3,참조!$E$3,참조!$E$2) -> 1000 | I39: =SUMIFS(지출기록_2월!$H$3:$H$312,지출기록_2월!$E$3:$E$312,B39,지출기록_2월!$F$3:$F$312,참조!$F$2) -> 0 | J39: =SUMIFS(지출기록_2월!$H$3:$H$312,지출기록_2월!$E$3:$E$312,B39,지출기록_2월!$F$3:$F$312,참조!$F$3) -> 0 | K39: =I39-J39 -> 0 | L39: =IF(B39>$B$2,H39,K39) -> 0 | M39: =$H39-$K39 -> 1000
B40: =DATE($A$1,C40,D40) -> 46056 | C40: 2 | D40: 3 | E40: =WEEKDAY(B40) -> 3 | F40: =IF($E40=참조!$B$2,참조!$C$2,IF($E40=참조!$B$3,참조!$C$3,IF($E40=참조!$B$4,참조!$C$4,IF($E40=참조!$B$5,참조!$C$5,IF($E40=참조!$B$6,참조!$C$6,IF($E40=참조!$B$7,참조!$C$7,IF($E40=참조!$B$8,참조!$C$8,""))))))) -> 火 | G40: =IF($F40=참조!$C$2,참조!$D$2,IF($F40=참조!$C$8,참조!$D$2,IF(COUNTIF('2026년휴일'!$B:$B,$B40)>0,참조!$D$2,참조!$D$3))) -> 勤 | H40: =IF($G40=참조!$D$3,참조!$E$3,참조!$E$2) -> 1000 | I40: =SUMIFS(지출기록_2월!$H$3:$H$312,지출기록_2월!$E$3:$E$312,B40,지출기록_2월!$F$3:$F$312,참조!$F$2) -> 0 | J40: =SUMIFS(지출기록_2월!$H$3:$H$312,지출기록_2월!$E$3:$E$312,B40,지출기록_2월!$F$3:$F$312,참조!$F$3) -> 0 | K40: =I40-J40 -> 0 | L40: =IF(B40>$B$2,H40,K40) -> 0 | M40: =$H40-$K40 -> 1000
B41: =DATE($A$1,C41,D41) -> 46057 | C41: 2 | D41: 4 | E41: =WEEKDAY(B41) -> 4 | F41: =IF($E41=참조!$B$2,참조!$C$2,IF($E41=참조!$B$3,참조!$C$3,IF($E41=참조!$B$4,참조!$C$4,IF($E41=참조!$B$5,참조!$C$5,IF($E41=참조!$B$6,참조!$C$6,IF($E41=참조!$B$7,참조!$C$7,IF($E41=참조!$B$8,참조!$C$8,""))))))) -> 水 | G41: =IF($F41=참조!$C$2,참조!$D$2,IF($F41=참조!$C$8,참조!$D$2,IF(COUNTIF('2026년휴일'!$B:$B,$B41)>0,참조!$D$2,참조!$D$3))) -> 勤 | H41: =IF($G41=참조!$D$3,참조!$E$3,참조!$E$2) -> 1000 | I41: =SUMIFS(지출기록_2월!$H$3:$H$312,지출기록_2월!$E$3:$E$312,B41,지출기록_2월!$F$3:$F$312,참조!$F$2) -> 0 | J41: =SUMIFS(지출기록_2월!$H$3:$H$312,지출기록_2월!$E$3:$E$312,B41,지출기록_2월!$F$3:$F$312,참조!$F$3) -> 0 | K41: =I41-J41 -> 0 | L41: =IF(B41>$B$2,H41,K41) -> 0 | M41: =$H41-$K41 -> 1000
B42: =DATE($A$1,C42,D42) -> 46058 | C42: 2 | D42: 5 | E42: =WEEKDAY(B42) -> 5 | F42: =IF($E42=참조!$B$2,참조!$C$2,IF($E42=참조!$B$3,참조!$C$3,IF($E42=참조!$B$4,참조!$C$4,IF($E42=참조!$B$5,참조!$C$5,IF($E42=참조!$B$6,참조!$C$6,IF($E42=참조!$B$7,참조!$C$7,IF($E42=참조!$B$8,참조!$C$8,""))))))) -> 木 | G42: =IF($F42=참조!$C$2,참조!$D$2,IF($F42=참조!$C$8,참조!$D$2,IF(COUNTIF('2026년휴일'!$B:$B,$B42)>0,참조!$D$2,참조!$D$3))) -> 勤 | H42: =IF($G42=참조!$D$3,참조!$E$3,참조!$E$2) -> 1000 | I42: =SUMIFS(지출기록_2월!$H$3:$H$312,지출기록_2월!$E$3:$E$312,B42,지출기록_2월!$F$3:$F$312,참조!$F$2) -> 0 | J42: =SUMIFS(지출기록_2월!$H$3:$H$312,지출기록_2월!$E$3:$E$312,B42,지출기록_2월!$F$3:$F$312,참조!$F$3) -> 0 | K42: =I42-J42 -> 0 | L42: =IF(B42>$B$2,H42,K42) -> 0 | M42: =$H42-$K42 -> 1000
B43: =DATE($A$1,C43,D43) -> 46059 | C43: 2 | D43: 6 | E43: =WEEKDAY(B43) -> 6 | F43: =IF($E43=참조!$B$2,참조!$C$2,IF($E43=참조!$B$3,참조!$C$3,IF($E43=참조!$B$4,참조!$C$4,IF($E43=참조!$B$5,참조!$C$5,IF($E43=참조!$B$6,참조!$C$6,IF($E43=참조!$B$7,참조!$C$7,IF($E43=참조!$B$8,참조!$C$8,""))))))) -> 金 | G43: =IF($F43=참조!$C$2,참조!$D$2,IF($F43=참조!$C$8,참조!$D$2,IF(COUNTIF('2026년휴일'!$B:$B,$B43)>0,참조!$D$2,참조!$D$3))) -> 勤 | H43: =IF($G43=참조!$D$3,참조!$E$3,참조!$E$2) -> 1000 | I43: =SUMIFS(지출기록_2월!$H$3:$H$312,지출기록_2월!$E$3:$E$312,B43,지출기록_2월!$F$3:$F$312,참조!$F$2) -> 0 | J43: =SUMIFS(지출기록_2월!$H$3:$H$312,지출기록_2월!$E$3:$E$312,B43,지출기록_2월!$F$3:$F$312,참조!$F$3) -> 0 | K43: =I43-J43 -> 0 | L43: =IF(B43>$B$2,H43,K43) -> 0 | M43: =$H43-$K43 -> 1000
B44: =DATE($A$1,C44,D44) -> 46060 | C44: 2 | D44: 7 | E44: =WEEKDAY(B44) -> 7 | F44: =IF($E44=참조!$B$2,참조!$C$2,IF($E44=참조!$B$3,참조!$C$3,IF($E44=참조!$B$4,참조!$C$4,IF($E44=참조!$B$5,참조!$C$5,IF($E44=참조!$B$6,참조!$C$6,IF($E44=참조!$B$7,참조!$C$7,IF($E44=참조!$B$8,참조!$C$8,""))))))) -> 土 | G44: =IF($F44=참조!$C$2,참조!$D$2,IF($F44=참조!$C$8,참조!$D$2,IF(COUNTIF('2026년휴일'!$B:$B,$B44)>0,참조!$D$2,참조!$D$3))) -> 休 | H44: =IF($G44=참조!$D$3,참조!$E$3,참조!$E$2) -> 5000 | I44: =SUMIFS(지출기록_2월!$H$3:$H$312,지출기록_2월!$E$3:$E$312,B44,지출기록_2월!$F$3:$F$312,참조!$F$2) -> 0 | J44: =SUMIFS(지출기록_2월!$H$3:$H$312,지출기록_2월!$E$3:$E$312,B44,지출기록_2월!$F$3:$F$312,참조!$F$3) -> 0 | K44: =I44-J44 -> 0 | L44: =IF(B44>$B$2,H44,K44) -> 0 | M44: =$H44-$K44 -> 5000
B45: =DATE($A$1,C45,D45) -> 46061 | C45: 2 | D45: 8 | E45: =WEEKDAY(B45) -> 1 | F45: =IF($E45=참조!$B$2,참조!$C$2,IF($E45=참조!$B$3,참조!$C$3,IF($E45=참조!$B$4,참조!$C$4,IF($E45=참조!$B$5,참조!$C$5,IF($E45=참조!$B$6,참조!$C$6,IF($E45=참조!$B$7,참조!$C$7,IF($E45=참조!$B$8,참조!$C$8,""))))))) -> 日 | G45: =IF($F45=참조!$C$2,참조!$D$2,IF($F45=참조!$C$8,참조!$D$2,IF(COUNTIF('2026년휴일'!$B:$B,$B45)>0,참조!$D$2,참조!$D$3))) -> 休 | H45: =IF($G45=참조!$D$3,참조!$E$3,참조!$E$2) -> 5000 | I45: =SUMIFS(지출기록_2월!$H$3:$H$312,지출기록_2월!$E$3:$E$312,B45,지출기록_2월!$F$3:$F$312,참조!$F$2) -> 0 | J45: =SUMIFS(지출기록_2월!$H$3:$H$312,지출기록_2월!$E$3:$E$312,B45,지출기록_2월!$F$3:$F$312,참조!$F$3) -> 0 | K45: =I45-J45 -> 0 | L45: =IF(B45>$B$2,H45,K45) -> 0 | M45: =$H45-$K45 -> 5000
B46: =DATE($A$1,C46,D46) -> 46062 | C46: 2 | D46: 9 | E46: =WEEKDAY(B46) -> 2 | F46: =IF($E46=참조!$B$2,참조!$C$2,IF($E46=참조!$B$3,참조!$C$3,IF($E46=참조!$B$4,참조!$C$4,IF($E46=참조!$B$5,참조!$C$5,IF($E46=참조!$B$6,참조!$C$6,IF($E46=참조!$B$7,참조!$C$7,IF($E46=참조!$B$8,참조!$C$8,""))))))) -> 月 | G46: =IF($F46=참조!$C$2,참조!$D$2,IF($F46=참조!$C$8,참조!$D$2,IF(COUNTIF('2026년휴일'!$B:$B,$B46)>0,참조!$D$2,참조!$D$3))) -> 勤 | H46: =IF($G46=참조!$D$3,참조!$E$3,참조!$E$2) -> 1000 | I46: =SUMIFS(지출기록_2월!$H$3:$H$312,지출기록_2월!$E$3:$E$312,B46,지출기록_2월!$F$3:$F$312,참조!$F$2) -> 0 | J46: =SUMIFS(지출기록_2월!$H$3:$H$312,지출기록_2월!$E$3:$E$312,B46,지출기록_2월!$F$3:$F$312,참조!$F$3) -> 0 | K46: =I46-J46 -> 0 | L46: =IF(B46>$B$2,H46,K46) -> 0 | M46: =$H46-$K46 -> 1000
B47: =DATE($A$1,C47,D47) -> 46063 | C47: 2 | D47: 10 | E47: =WEEKDAY(B47) -> 3 | F47: =IF($E47=참조!$B$2,참조!$C$2,IF($E47=참조!$B$3,참조!$C$3,IF($E47=참조!$B$4,참조!$C$4,IF($E47=참조!$B$5,참조!$C$5,IF($E47=참조!$B$6,참조!$C$6,IF($E47=참조!$B$7,참조!$C$7,IF($E47=참조!$B$8,참조!$C$8,""))))))) -> 火 | G47: =IF($F47=참조!$C$2,참조!$D$2,IF($F47=참조!$C$8,참조!$D$2,IF(COUNTIF('2026년휴일'!$B:$B,$B47)>0,참조!$D$2,참조!$D$3))) -> 勤 | H47: =IF($G47=참조!$D$3,참조!$E$3,참조!$E$2) -> 1000 | I47: =SUMIFS(지출기록_2월!$H$3:$H$312,지출기록_2월!$E$3:$E$312,B47,지출기록_2월!$F$3:$F$312,참조!$F$2) -> 0 | J47: =SUMIFS(지출기록_2월!$H$3:$H$312,지출기록_2월!$E$3:$E$312,B47,지출기록_2월!$F$3:$F$312,참조!$F$3) -> 0 | K47: =I47-J47 -> 0 | L47: =IF(B47>$B$2,H47,K47) -> 0 | M47: =$H47-$K47 -> 1000
B48: =DATE($A$1,C48,D48) -> 46064 | C48: 2 | D48: 11 | E48: =WEEKDAY(B48) -> 4 | F48: =IF($E48=참조!$B$2,참조!$C$2,IF($E48=참조!$B$3,참조!$C$3,IF($E48=참조!$B$4,참조!$C$4,IF($E48=참조!$B$5,참조!$C$5,IF($E48=참조!$B$6,참조!$C$6,IF($E48=참조!$B$7,참조!$C$7,IF($E48=참조!$B$8,참조!$C$8,""))))))) -> 水 | G48: =IF($F48=참조!$C$2,참조!$D$2,IF($F48=참조!$C$8,참조!$D$2,IF(COUNTIF('2026년휴일'!$B:$B,$B48)>0,참조!$D$2,참조!$D$3))) -> 休 | H48: =IF($G48=참조!$D$3,참조!$E$3,참조!$E$2) -> 5000 | I48: =SUMIFS(지출기록_2월!$H$3:$H$312,지출기록_2월!$E$3:$E$312,B48,지출기록_2월!$F$3:$F$312,참조!$F$2) -> 0 | J48: =SUMIFS(지출기록_2월!$H$3:$H$312,지출기록_2월!$E$3:$E$312,B48,지출기록_2월!$F$3:$F$312,참조!$F$3) -> 0 | K48: =I48-J48 -> 0 | L48: =IF(B48>$B$2,H48,K48) -> 0 | M48: =$H48-$K48 -> 5000
B49: =DATE($A$1,C49,D49) -> 46065 | C49: 2 | D49: 12 | E49: =WEEKDAY(B49) -> 5 | F49: =IF($E49=참조!$B$2,참조!$C$2,IF($E49=참조!$B$3,참조!$C$3,IF($E49=참조!$B$4,참조!$C$4,IF($E49=참조!$B$5,참조!$C$5,IF($E49=참조!$B$6,참조!$C$6,IF($E49=참조!$B$7,참조!$C$7,IF($E49=참조!$B$8,참조!$C$8,""))))))) -> 木 | G49: =IF($F49=참조!$C$2,참조!$D$2,IF($F49=참조!$C$8,참조!$D$2,IF(COUNTIF('2026년휴일'!$B:$B,$B49)>0,참조!$D$2,참조!$D$3))) -> 勤 | H49: =IF($G49=참조!$D$3,참조!$E$3,참조!$E$2) -> 1000 | I49: =SUMIFS(지출기록_2월!$H$3:$H$312,지출기록_2월!$E$3:$E$312,B49,지출기록_2월!$F$3:$F$312,참조!$F$2) -> 0 | J49: =SUMIFS(지출기록_2월!$H$3:$H$312,지출기록_2월!$E$3:$E$312,B49,지출기록_2월!$F$3:$F$312,참조!$F$3) -> 0 | K49: =I49-J49 -> 0 | L49: =IF(B49>$B$2,H49,K49) -> 0 | M49: =$H49-$K49 -> 1000
... B65: =DATE($A$1,C65,D65) -> 46081 | C65: 2 | D65: 28 | E65: =WEEKDAY(B65) -> 7 | F65: =IF($E65=참조!$B$2,참조!$C$2,IF($E65=참조!$B$3,참조!$C$3,IF($E65=참조!$B$4,참조!$C$4,IF($E65=참조!$B$5,참조!$C$5,IF($E65=참조!$B$6,참조!$C$6,IF($E65=참조!$B$7,참조!$C$7,IF($E65=참조!$B$8,참조!$C$8,""))))))) -> 土 | G65: =IF($F65=참조!$C$2,참조!$D$2,IF($F65=참조!$C$8,참조!$D$2,IF(COUNTIF('2026년휴일'!$B:$B,$B65)>0,참조!$D$2,참조!$D$3))) -> 休 | H65: =IF($G65=참조!$D$3,참조!$E$3,참조!$E$2) -> 5000 | I65: =SUMIFS(지출기록_2월!$H$3:$H$312,지출기록_2월!$E$3:$E$312,B65,지출기록_2월!$F$3:$F$312,참조!$F$2) -> 0 | J65: =SUMIFS(지출기록_2월!$H$3:$H$312,지출기록_2월!$E$3:$E$312,B65,지출기록_2월!$F$3:$F$312,참조!$F$3) -> 0 | K65: =I65-J65 -> 0 | L65: =IF(B65>$B$2,H65,K65) -> 0 | M65: =$H65-$K65 -> 5000
B66: =DATE($A$1,C66,D66) -> 46082 | C66: 3 | D66: 1 | E66: =WEEKDAY(B66) -> 1 | F66: =IF($E66=참조!$B$2,참조!$C$2,IF($E66=참조!$B$3,참조!$C$3,IF($E66=참조!$B$4,참조!$C$4,IF($E66=참조!$B$5,참조!$C$5,IF($E66=참조!$B$6,참조!$C$6,IF($E66=참조!$B$7,참조!$C$7,IF($E66=참조!$B$8,참조!$C$8,""))))))) -> 日 | G66: =IF($F66=참조!$C$2,참조!$D$2,IF($F66=참조!$C$8,참조!$D$2,IF(COUNTIF('2026년휴일'!$B:$B,$B66)>0,참조!$D$2,참조!$D$3))) -> 休 | H66: =IF($G66=참조!$D$3,참조!$E$3,참조!$E$2) -> 5000 | I66: =SUMIFS(지출기록_3월!$H$3:$H$312,지출기록_3월!$E$3:$E$312,B66,지출기록_3월!$F$3:$F$312,참조!$F$2) -> 0 | J66: =SUMIFS(지출기록_3월!$H$3:$H$312,지출기록_3월!$E$3:$E$312,B66,지출기록_3월!$F$3:$F$312,참조!$F$3) -> 0 | K66: =I66-J66 -> 0 | L66: =IF(B66>$B$2,H66,K66) -> 0 | M66: =$H66-$K66 -> 5000
B67: =DATE($A$1,C67,D67) -> 46083 | C67: 3 | D67: 2 | E67: =WEEKDAY(B67) -> 2 | F67: =IF($E67=참조!$B$2,참조!$C$2,IF($E67=참조!$B$3,참조!$C$3,IF($E67=참조!$B$4,참조!$C$4,IF($E67=참조!$B$5,참조!$C$5,IF($E67=참조!$B$6,참조!$C$6,IF($E67=참조!$B$7,참조!$C$7,IF($E67=참조!$B$8,참조!$C$8,""))))))) -> 月 | G67: =IF($F67=참조!$C$2,참조!$D$2,IF($F67=참조!$C$8,참조!$D$2,IF(COUNTIF('2026년휴일'!$B:$B,$B67)>0,참조!$D$2,참조!$D$3))) -> 勤 | H67: =IF($G67=참조!$D$3,참조!$E$3,참조!$E$2) -> 1000 | I67: =SUMIFS(지출기록_3월!$H$3:$H$312,지출기록_3월!$E$3:$E$312,B67,지출기록_3월!$F$3:$F$312,참조!$F$2) -> 0 | J67: =SUMIFS(지출기록_3월!$H$3:$H$312,지출기록_3월!$E$3:$E$312,B67,지출기록_3월!$F$3:$F$312,참조!$F$3) -> 0 | K67: =I67-J67 -> 0 | L67: =IF(B67>$B$2,H67,K67) -> 0 | M67: =$H67-$K67 -> 1000
B68: =DATE($A$1,C68,D68) -> 46084 | C68: 3 | D68: 3 | E68: =WEEKDAY(B68) -> 3 | F68: =IF($E68=참조!$B$2,참조!$C$2,IF($E68=참조!$B$3,참조!$C$3,IF($E68=참조!$B$4,참조!$C$4,IF($E68=참조!$B$5,참조!$C$5,IF($E68=참조!$B$6,참조!$C$6,IF($E68=참조!$B$7,참조!$C$7,IF($E68=참조!$B$8,참조!$C$8,""))))))) -> 火 | G68: =IF($F68=참조!$C$2,참조!$D$2,IF($F68=참조!$C$8,참조!$D$2,IF(COUNTIF('2026년휴일'!$B:$B,$B68)>0,참조!$D$2,참조!$D$3))) -> 勤 | H68: =IF($G68=참조!$D$3,참조!$E$3,참조!$E$2) -> 1000 | I68: =SUMIFS(지출기록_3월!$H$3:$H$312,지출기록_3월!$E$3:$E$312,B68,지출기록_3월!$F$3:$F$312,참조!$F$2) -> 0 | J68: =SUMIFS(지출기록_3월!$H$3:$H$312,지출기록_3월!$E$3:$E$312,B68,지출기록_3월!$F$3:$F$312,참조!$F$3) -> 0 | K68: =I68-J68 -> 0 | L68: =IF(B68>$B$2,H68,K68) -> 0 | M68: =$H68-$K68 -> 1000
B69: =DATE($A$1,C69,D69) -> 46085 | C69: 3 | D69: 4 | E69: =WEEKDAY(B69) -> 4 | F69: =IF($E69=참조!$B$2,참조!$C$2,IF($E69=참조!$B$3,참조!$C$3,IF($E69=참조!$B$4,참조!$C$4,IF($E69=참조!$B$5,참조!$C$5,IF($E69=참조!$B$6,참조!$C$6,IF($E69=참조!$B$7,참조!$C$7,IF($E69=참조!$B$8,참조!$C$8,""))))))) -> 水 | G69: =IF($F69=참조!$C$2,참조!$D$2,IF($F69=참조!$C$8,참조!$D$2,IF(COUNTIF('2026년휴일'!$B:$B,$B69)>0,참조!$D$2,참조!$D$3))) -> 勤 | H69: =IF($G69=참조!$D$3,참조!$E$3,참조!$E$2) -> 1000 | I69: =SUMIFS(지출기록_3월!$H$3:$H$312,지출기록_3월!$E$3:$E$312,B69,지출기록_3월!$F$3:$F$312,참조!$F$2) -> 0 | J69: =SUMIFS(지출기록_3월!$H$3:$H$312,지출기록_3월!$E$3:$E$312,B69,지출기록_3월!$F$3:$F$312,참조!$F$3) -> 0 | K69: =I69-J69 -> 0 | L69: =IF(B69>$B$2,H69,K69) -> 0 | M69: =$H69-$K69 -> 1000
B70: =DATE($A$1,C70,D70) -> 46086 | C70: 3 | D70: 5 | E70: =WEEKDAY(B70) -> 5 | F70: =IF($E70=참조!$B$2,참조!$C$2,IF($E70=참조!$B$3,참조!$C$3,IF($E70=참조!$B$4,참조!$C$4,IF($E70=참조!$B$5,참조!$C$5,IF($E70=참조!$B$6,참조!$C$6,IF($E70=참조!$B$7,참조!$C$7,IF($E70=참조!$B$8,참조!$C$8,""))))))) -> 木 | G70: =IF($F70=참조!$C$2,참조!$D$2,IF($F70=참조!$C$8,참조!$D$2,IF(COUNTIF('2026년휴일'!$B:$B,$B70)>0,참조!$D$2,참조!$D$3))) -> 勤 | H70: =IF($G70=참조!$D$3,참조!$E$3,참조!$E$2) -> 1000 | I70: =SUMIFS(지출기록_3월!$H$3:$H$312,지출기록_3월!$E$3:$E$312,B70,지출기록_3월!$F$3:$F$312,참조!$F$2) -> 0 | J70: =SUMIFS(지출기록_3월!$H$3:$H$312,지출기록_3월!$E$3:$E$312,B70,지출기록_3월!$F$3:$F$312,참조!$F$3) -> 0 | K70: =I70-J70 -> 0 | L70: =IF(B70>$B$2,H70,K70) -> 0 | M70: =$H70-$K70 -> 1000
B71: =DATE($A$1,C71,D71) -> 46087 | C71: 3 | D71: 6 | E71: =WEEKDAY(B71) -> 6 | F71: =IF($E71=참조!$B$2,참조!$C$2,IF($E71=참조!$B$3,참조!$C$3,IF($E71=참조!$B$4,참조!$C$4,IF($E71=참조!$B$5,참조!$C$5,IF($E71=참조!$B$6,참조!$C$6,IF($E71=참조!$B$7,참조!$C$7,IF($E71=참조!$B$8,참조!$C$8,""))))))) -> 金 | G71: =IF($F71=참조!$C$2,참조!$D$2,IF($F71=참조!$C$8,참조!$D$2,IF(COUNTIF('2026년휴일'!$B:$B,$B71)>0,참조!$D$2,참조!$D$3))) -> 勤 | H71: =IF($G71=참조!$D$3,참조!$E$3,참조!$E$2) -> 1000 | I71: =SUMIFS(지출기록_3월!$H$3:$H$312,지출기록_3월!$E$3:$E$312,B71,지출기록_3월!$F$3:$F$312,참조!$F$2) -> 0 | J71: =SUMIFS(지출기록_3월!$H$3:$H$312,지출기록_3월!$E$3:$E$312,B71,지출기록_3월!$F$3:$F$312,참조!$F$3) -> 0 | K71: =I71-J71 -> 0 | L71: =IF(B71>$B$2,H71,K71) -> 0 | M71: =$H71-$K71 -> 1000
B72: =DATE($A$1,C72,D72) -> 46088 | C72: 3 | D72: 7 | E72: =WEEKDAY(B72) -> 7 | F72: =IF($E72=참조!$B$2,참조!$C$2,IF($E72=참조!$B$3,참조!$C$3,IF($E72=참조!$B$4,참조!$C$4,IF($E72=참조!$B$5,참조!$C$5,IF($E72=참조!$B$6,참조!$C$6,IF($E72=참조!$B$7,참조!$C$7,IF($E72=참조!$B$8,참조!$C$8,""))))))) -> 土 | G72: =IF($F72=참조!$C$2,참조!$D$2,IF($F72=참조!$C$8,참조!$D$2,IF(COUNTIF('2026년휴일'!$B:$B,$B72)>0,참조!$D$2,참조!$D$3))) -> 休 | H72: =IF($G72=참조!$D$3,참조!$E$3,참조!$E$2) -> 5000 | I72: =SUMIFS(지출기록_3월!$H$3:$H$312,지출기록_3월!$E$3:$E$312,B72,지출기록_3월!$F$3:$F$312,참조!$F$2) -> 0 | J72: =SUMIFS(지출기록_3월!$H$3:$H$312,지출기록_3월!$E$3:$E$312,B72,지출기록_3월!$F$3:$F$312,참조!$F$3) -> 0 | K72: =I72-J72 -> 0 | L72: =IF(B72>$B$2,H72,K72) -> 0 | M72: =$H72-$K72 -> 5000
B73: =DATE($A$1,C73,D73) -> 46089 | C73: 3 | D73: 8 | E73: =WEEKDAY(B73) -> 1 | F73: =IF($E73=참조!$B$2,참조!$C$2,IF($E73=참조!$B$3,참조!$C$3,IF($E73=참조!$B$4,참조!$C$4,IF($E73=참조!$B$5,참조!$C$5,IF($E73=참조!$B$6,참조!$C$6,IF($E73=참조!$B$7,참조!$C$7,IF($E73=참조!$B$8,참조!$C$8,""))))))) -> 日 | G73: =IF($F73=참조!$C$2,참조!$D$2,IF($F73=참조!$C$8,참조!$D$2,IF(COUNTIF('2026년휴일'!$B:$B,$B73)>0,참조!$D$2,참조!$D$3))) -> 休 | H73: =IF($G73=참조!$D$3,참조!$E$3,참조!$E$2) -> 5000 | I73: =SUMIFS(지출기록_3월!$H$3:$H$312,지출기록_3월!$E$3:$E$312,B73,지출기록_3월!$F$3:$F$312,참조!$F$2) -> 0 | J73: =SUMIFS(지출기록_3월!$H$3:$H$312,지출기록_3월!$E$3:$E$312,B73,지출기록_3월!$F$3:$F$312,참조!$F$3) -> 0 | K73: =I73-J73 -> 0 | L73: =IF(B73>$B$2,H73,K73) -> 0 | M73: =$H73-$K73 -> 5000
...

Sheet 지출기록_1월
A1: 년도 | B1: ='2026년달력'!A1 -> 2026
A2: 월 | B2: 1 | E2: 날짜 | F2: 구분 | G2: 수단 | H2: 액수 | I2: 내용 | J2: 비고
D3: 1 | E3: =DATE($B$1,$B$2,$D3) -> 46023
D4: 1 | E4: =DATE($B$1,$B$2,$D4) -> 46023
D5: 1 | E5: =DATE($B$1,$B$2,$D5) -> 46023
D6: 1 | E6: =DATE($B$1,$B$2,$D6) -> 46023
D7: 1 | E7: =DATE($B$1,$B$2,$D7) -> 46023
D8: 1 | E8: =DATE($B$1,$B$2,$D8) -> 46023
D9: 1 | E9: =DATE($B$1,$B$2,$D9) -> 46023
D10: 1 | E10: =DATE($B$1,$B$2,$D10) -> 46023
D11: 1 | E11: =DATE($B$1,$B$2,$D11) -> 46023
D12: 1 | E12: =DATE($B$1,$B$2,$D12) -> 46023
D13: 2 | E13: =DATE($B$1,$B$2,$D13) -> 46024
D14: 2 | E14: =DATE($B$1,$B$2,$D14) -> 46024
... D312: 31 | E312: =DATE($B$1,$B$2,$D312) -> 46053

Sheet 지출기록_2월
A1: 년도 | B1: ='2026년달력'!A1 -> 2026
A2: 월 | B2: 2 | E2: 날짜 | F2: 구분 | G2: 수단 | H2: 액수 | I2: 내용 | J2: 비고
D3: 1 | E3: =DATE($B$1,$B$2,$D3) -> 46054
D4: 1 | E4: =DATE($B$1,$B$2,$D4) -> 46054
D5: 1 | E5: =DATE($B$1,$B$2,$D5) -> 46054
D6: 1 | E6: =DATE($B$1,$B$2,$D6) -> 46054
D7: 1 | E7: =DATE($B$1,$B$2,$D7) -> 46054
D8: 1 | E8: =DATE($B$1,$B$2,$D8) -> 46054
D9: 1 | E9: =DATE($B$1,$B$2,$D9) -> 46054
D10: 1 | E10: =DATE($B$1,$B$2,$D10) -> 46054
D11: 1 | E11: =DATE($B$1,$B$2,$D11) -> 46054
D12: 1 | E12: =DATE($B$1,$B$2,$D12) -> 46054
D13: 2 | E13: =DATE($B$1,$B$2,$D13) -> 46055
D14: 2 | E14: =DATE($B$1,$B$2,$D14) -> 46055
... D282: 28 | E282: =DATE($B$1,$B$2,$D282) -> 46081

Sheet 지출기록_3월
A1: 년도 | B1: ='2026년달력'!A1 -> 2026
A2: 월 | B2: 3 | E2: 날짜 | F2: 구분 | G2: 수단 | H2: 액수 | I2: 내용 | J2: 비고
D3: 1 | E3: =DATE($B$1,$B$2,$D3) -> 46082
D4: 1 | E4: =DATE($B$1,$B$2,$D4) -> 46082
D5: 1 | E5: =DATE($B$1,$B$2,$D5) -> 46082
D6: 1 | E6: =DATE($B$1,$B$2,$D6) -> 46082
D7: 1 | E7: =DATE($B$1,$B$2,$D7) -> 46082
D8: 1 | E8: =DATE($B$1,$B$2,$D8) -> 46082
D9: 1 | E9: =DATE($B$1,$B$2,$D9) -> 46082
D10: 1 | E10: =DATE($B$1,$B$2,$D10) -> 46082
D11: 1 | E11: =DATE($B$1,$B$2,$D11) -> 46082
D12: 1 | E12: =DATE($B$1,$B$2,$D12) -> 46082
D13: 2 | E13: =DATE($B$1,$B$2,$D13) -> 46083
D14: 2 | E14: =DATE($B$1,$B$2,$D14) -> 46083
... D312: 31 | E312: =DATE($B$1,$B$2,$D312) -> 46112

Sheet 지출기록_4월
A1: 년도 | B1: ='2026년달력'!A1 -> 2026
A2: 월 | B2: 4 | E2: 날짜 | F2: 구분 | G2: 수단 | H2: 액수 | I2: 내용 | J2: 비고
D3: 1 | E3: =DATE($B$1,$B$2,$D3) -> 46113
D4: 1 | E4: =DATE($B$1,$B$2,$D4) -> 46113
D5: 1 | E5: =DATE($B$1,$B$2,$D5) -> 46113
D6: 1 | E6: =DATE($B$1,$B$2,$D6) -> 46113
D7: 1 | E7: =DATE($B$1,$B$2,$D7) -> 46113
D8: 1 | E8: =DATE($B$1,$B$2,$D8) -> 46113
D9: 1 | E9: =DATE($B$1,$B$2,$D9) -> 46113
D10: 1 | E10: =DATE($B$1,$B$2,$D10) -> 46113
D11: 1 | E11: =DATE($B$1,$B$2,$D11) -> 46113
D12: 1 | E12: =DATE($B$1,$B$2,$D12) -> 46113
D13: 2 | E13: =DATE($B$1,$B$2,$D13) -> 46114
D14: 2 | E14: =DATE($B$1,$B$2,$D14) -> 46114
... D302: 30 | E302: =DATE($B$1,$B$2,$D302) -> 46142

Sheet 지출기록_5월
A1: 년도 | B1: ='2026년달력'!A1 -> 2026
A2: 월 | B2: 5 | E2: 날짜 | F2: 구분 | G2: 수단 | H2: 액수 | I2: 내용 | J2: 비고
D3: 1 | E3: =DATE($B$1,$B$2,$D3) -> 46143
D4: 1 | E4: =DATE($B$1,$B$2,$D4) -> 46143
D5: 1 | E5: =DATE($B$1,$B$2,$D5) -> 46143
D6: 1 | E6: =DATE($B$1,$B$2,$D6) -> 46143
D7: 1 | E7: =DATE($B$1,$B$2,$D7) -> 46143
D8: 1 | E8: =DATE($B$1,$B$2,$D8) -> 46143
D9: 1 | E9: =DATE($B$1,$B$2,$D9) -> 46143
D10: 1 | E10: =DATE($B$1,$B$2,$D10) -> 46143
D11: 1 | E11: =DATE($B$1,$B$2,$D11) -> 46143
D12: 1 | E12: =DATE($B$1,$B$2,$D12) -> 46143
D13: 2 | E13: =DATE($B$1,$B$2,$D13) -> 46144
D14: 2 | E14: =DATE($B$1,$B$2,$D14) -> 46144
... D312: 31 | E312: =DATE($B$1,$B$2,$D312) -> 46173

Sheet 지출기록_6월
A1: 년도 | B1: ='2026년달력'!A1 -> 2026
A2: 월 | B2: 6 | E2: 날짜 | F2: 구분 | G2: 수단 | H2: 액수 | I2: 내용 | J2: 비고
D3: 1 | E3: =DATE($B$1,$B$2,$D3) -> 46174
D4: 1 | E4: =DATE($B$1,$B$2,$D4) -> 46174
D5: 1 | E5: =DATE($B$1,$B$2,$D5) -> 46174
D6: 1 | E6: =DATE($B$1,$B$2,$D6) -> 46174
D7: 1 | E7: =DATE($B$1,$B$2,$D7) -> 46174
D8: 1 | E8: =DATE($B$1,$B$2,$D8) -> 46174
D9: 1 | E9: =DATE($B$1,$B$2,$D9) -> 46174
D10: 1 | E10: =DATE($B$1,$B$2,$D10) -> 46174
D11: 1 | E11: =DATE($B$1,$B$2,$D11) -> 46174
D12: 1 | E12: =DATE($B$1,$B$2,$D12) -> 46174
D13: 2 | E13: =DATE($B$1,$B$2,$D13) -> 46175
D14: 2 | E14: =DATE($B$1,$B$2,$D14) -> 46175
... D302: 30 | E302: =DATE($B$1,$B$2,$D302) -> 46203

Sheet 지출기록_7월
A1: 년도 | B1: ='2026년달력'!A1 -> 2026
A2: 월 | B2: 7 | E2: 날짜 | F2: 구분 | G2: 수단 | H2: 액수 | I2: 내용 | J2: 비고
D3: 1 | E3: =DATE($B$1,$B$2,$D3) -> 46204
D4: 1 | E4: =DATE($B$1,$B$2,$D4) -> 46204
D5: 1 | E5: =DATE($B$1,$B$2,$D5) -> 46204
D6: 1 | E6: =DATE($B$1,$B$2,$D6) -> 46204
D7: 1 | E7: =DATE($B$1,$B$2,$D7) -> 46204
D8: 1 | E8: =DATE($B$1,$B$2,$D8) -> 46204
D9: 1 | E9: =DATE($B$1,$B$2,$D9) -> 46204
D10: 1 | E10: =DATE($B$1,$B$2,$D10) -> 46204
D11: 1 | E11: =DATE($B$1,$B$2,$D11) -> 46204
D12: 1 | E12: =DATE($B$1,$B$2,$D12) -> 46204
D13: 2 | E13: =DATE($B$1,$B$2,$D13) -> 46205
D14: 2 | E14: =DATE($B$1,$B$2,$D14) -> 46205
... D312: 31 | E312: =DATE($B$1,$B$2,$D312) -> 46234

Sheet 지출기록_8월
A1: 년도 | B1: ='2026년달력'!A1 -> 2026
A2: 월 | B2: 8 | E2: 날짜 | F2: 구분 | G2: 수단 | H2: 액수 | I2: 내용 | J2: 비고
D3: 1 | E3: =DATE($B$1,$B$2,$D3) -> 46235
D4: 1 | E4: =DATE($B$1,$B$2,$D4) -> 46235
D5: 1 | E5: =DATE($B$1,$B$2,$D5) -> 46235
D6: 1 | E6: =DATE($B$1,$B$2,$D6) -> 46235
D7: 1 | E7: =DATE($B$1,$B$2,$D7) -> 46235
D8: 1 | E8: =DATE($B$1,$B$2,$D8) -> 46235
D9: 1 | E9: =DATE($B$1,$B$2,$D9) -> 46235
D10: 1 | E10: =DATE($B$1,$B$2,$D10) -> 46235
D11: 1 | E11: =DATE($B$1,$B$2,$D11) -> 46235
D12: 1 | E12: =DATE($B$1,$B$2,$D12) -> 46235
D13: 2 | E13: =DATE($B$1,$B$2,$D13) -> 46236
D14: 2 | E14: =DATE($B$1,$B$2,$D14) -> 46236
... D314: 31 | E314: =DATE($B$1,$B$2,$D314) -> 46265

Sheet 지출기록_9월
A1: 년도 | B1: ='2026년달력'!A1 -> 2026
A2: 월 | B2: 9 | E2: 날짜 | F2: 구분 | G2: 수단 | H2: 액수 | I2: 내용 | J2: 비고
D3: 1 | E3: =DATE($B$1,$B$2,$D3) -> 46266
D4: 1 | E4: =DATE($B$1,$B$2,$D4) -> 46266
D5: 1 | E5: =DATE($B$1,$B$2,$D5) -> 46266
D6: 1 | E6: =DATE($B$1,$B$2,$D6) -> 46266
D7: 1 | E7: =DATE($B$1,$B$2,$D7) -> 46266
D8: 1 | E8: =DATE($B$1,$B$2,$D8) -> 46266
D9: 1 | E9: =DATE($B$1,$B$2,$D9) -> 46266
D10: 1 | E10: =DATE($B$1,$B$2,$D10) -> 46266
D11: 1 | E11: =DATE($B$1,$B$2,$D11) -> 46266
D12: 1 | E12: =DATE($B$1,$B$2,$D12) -> 46266
D13: 2 | E13: =DATE($B$1,$B$2,$D13) -> 46267
D14: 2 | E14: =DATE($B$1,$B$2,$D14) -> 46267
... D302: 30 | E302: =DATE($B$1,$B$2,$D302) -> 46295

Sheet 지출기록_10월
A1: 년도 | B1: ='2026년달력'!A1 -> 2026
A2: 월 | B2: 10 | E2: 날짜 | F2: 구분 | G2: 수단 | H2: 액수 | I2: 내용 | J2: 비고
D3: 1 | E3: =DATE($B$1,$B$2,$D3) -> 46296
D4: 1 | E4: =DATE($B$1,$B$2,$D4) -> 46296
D5: 1 | E5: =DATE($B$1,$B$2,$D5) -> 46296
D6: 1 | E6: =DATE($B$1,$B$2,$D6) -> 46296
D7: 1 | E7: =DATE($B$1,$B$2,$D7) -> 46296
D8: 1 | E8: =DATE($B$1,$B$2,$D8) -> 46296
D9: 1 | E9: =DATE($B$1,$B$2,$D9) -> 46296
D10: 1 | E10: =DATE($B$1,$B$2,$D10) -> 46296
D11: 1 | E11: =DATE($B$1,$B$2,$D11) -> 46296
D12: 1 | E12: =DATE($B$1,$B$2,$D12) -> 46296
D13: 2 | E13: =DATE($B$1,$B$2,$D13) -> 46297
D14: 2 | E14: =DATE($B$1,$B$2,$D14) -> 46297
... D312: 31 | E312: =DATE($B$1,$B$2,$D312) -> 46326

Sheet 지출기록_11월
A1: 년도 | B1: ='2026년달력'!A1 -> 2026
A2: 월 | B2: 11 | E2: 날짜 | F2: 구분 | G2: 수단 | H2: 액수 | I2: 내용 | J2: 비고
D3: 1 | E3: =DATE($B$1,$B$2,$D3) -> 46327
D4: 1 | E4: =DATE($B$1,$B$2,$D4) -> 46327
D5: 1 | E5: =DATE($B$1,$B$2,$D5) -> 46327
D6: 1 | E6: =DATE($B$1,$B$2,$D6) -> 46327
D7: 1 | E7: =DATE($B$1,$B$2,$D7) -> 46327
D8: 1 | E8: =DATE($B$1,$B$2,$D8) -> 46327
D9: 1 | E9: =DATE($B$1,$B$2,$D9) -> 46327
D10: 1 | E10: =DATE($B$1,$B$2,$D10) -> 46327
D11: 1 | E11: =DATE($B$1,$B$2,$D11) -> 46327
D12: 1 | E12: =DATE($B$1,$B$2,$D12) -> 46327
D13: 2 | E13: =DATE($B$1,$B$2,$D13) -> 46328
D14: 2 | E14: =DATE($B$1,$B$2,$D14) -> 46328
... D302: 30 | E302: =DATE($B$1,$B$2,$D302) -> 46356

Sheet 지출기록_12월
A1: 년도 | B1: ='2026년달력'!A1 -> 2026
A2: 월 | B2: 12 | E2: 날짜 | F2: 구분 | G2: 수단 | H2: 액수 | I2: 내용 | J2: 비고
D3: 1 | E3: =DATE($B$1,$B$2,$D3) -> 46357
D4: 1 | E4: =DATE($B$1,$B$2,$D4) -> 46357
D5: 1 | E5: =DATE($B$1,$B$2,$D5) -> 46357
D6: 1 | E6: =DATE($B$1,$B$2,$D6) -> 46357
D7: 1 | E7: =DATE($B$1,$B$2,$D7) -> 46357
D8: 1 | E8: =DATE($B$1,$B$2,$D8) -> 46357
D9: 1 | E9: =DATE($B$1,$B$2,$D9) -> 46357
D10: 1 | E10: =DATE($B$1,$B$2,$D10) -> 46357
D11: 1 | E11: =DATE($B$1,$B$2,$D11) -> 46357
D12: 1 | E12: =DATE($B$1,$B$2,$D12) -> 46357
D13: 2 | E13: =DATE($B$1,$B$2,$D13) -> 46358
D14: 2 | E14: =DATE($B$1,$B$2,$D14) -> 46358
... D312: 31 | E312: =DATE($B$1,$B$2,$D312) -> 46387

Sheet 지출기록_양식
A1: 년도 | B1: 2025
A2: 월 | B2: 1 | E2: 날짜 | F2: 구분 | G2: 수단 | H2: 액수 | I2: 내용 | J2: 비고
D3: 1 | E3: =DATE($B$1,$B$2,$D3) -> 45658
D4: 1 | E4: =DATE($B$1,$B$2,$D4) -> 45658
D5: 1 | E5: =DATE($B$1,$B$2,$D5) -> 45658
D6: 1 | E6: =DATE($B$1,$B$2,$D6) -> 45658
D7: 1 | E7: =DATE($B$1,$B$2,$D7) -> 45658
D8: 1 | E8: =DATE($B$1,$B$2,$D8) -> 45658
D9: 1 | E9: =DATE($B$1,$B$2,$D9) -> 45658
D10: 1 | E10: =DATE($B$1,$B$2,$D10) -> 45658
D11: 1 | E11: =DATE($B$1,$B$2,$D11) -> 45658
D12: 1 | E12: =DATE($B$1,$B$2,$D12) -> 45658
D13: 2 | E13: =DATE($B$1,$B$2,$D13) -> 45659
D14: 2 | E14: =DATE($B$1,$B$2,$D14) -> 45659
... D312: 31 | E312: =DATE($B$1,$B$2,$D312) -> 45688
